Traceback (most recent call last):
  File "/Users/amrehassan/Library/Python/3.9/lib/python/site-packages/starlette/responses.py", line 353, in __call__
    stat_result = await anyio.to_thread.run_sync(os.stat, self.path)
  File "/Users/amrehassan/Library/Python/3.9/lib/python/site-packages/anyio/to_thread.py", line 56, in run_sync
    return await get_async_backend().run_sync_in_worker_thread(
  File "/Users/amrehassan/Library/Python/3.9/lib/python/site-packages/anyio/_backends/_asyncio.py", line 2476, in run_sync_in_worker_thread
    return await future
  File "/Users/amrehassan/Library/Python/3.9/lib/python/site-packages/anyio/_backends/_asyncio.py", line 967, in run
    result = context.run(func, *args)
FileNotFoundError: [Errno 2] No such file or directory: '/var/folders/ld/jp4094td2sz94sf512yktxlw0000gn/T/docx_processor/8a7da7a8-eacb-4155-9a4f-3a0e217bc355/output_test_template.pdf'

During handling of the above exception, another exception occurred:

Traceback (most recent call last):
  File "/Users/amrehassan/Library/Python/3.9/lib/python/site-packages/starlette/middleware/errors.py", line 164, in __call__
    await self.app(scope, receive, _send)
  File "/Users/amrehassan/Library/Python/3.9/lib/python/site-packages/starlette/middleware/cors.py", line 85, in __call__
    await self.app(scope, receive, send)
  File "/Users/amrehassan/Library/Python/3.9/lib/python/site-packages/starlette/middleware/exceptions.py", line 63, in __call__
    await wrap_app_handling_exceptions(self.app, conn)(scope, receive, send)
  File "/Users/amrehassan/Library/Python/3.9/lib/python/site-packages/starlette/_exception_handler.py", line 53, in wrapped_app
    raise exc
  File "/Users/amrehassan/Library/Python/3.9/lib/python/site-packages/starlette/_exception_handler.py", line 42, in wrapped_app
    await app(scope, receive, sender)
  File "/Users/amrehassan/Library/Python/3.9/lib/python/site-packages/starlette/routing.py", line 716, in __call__
    await self.middleware_stack(scope, receive, send)
  File "/Users/amrehassan/Library/Python/3.9/lib/python/site-packages/starlette/routing.py", line 736, in app
    await route.handle(scope, receive, send)
  File "/Users/amrehassan/Library/Python/3.9/lib/python/site-packages/starlette/routing.py", line 290, in handle
    await self.app(scope, receive, send)
  File "/Users/amrehassan/Library/Python/3.9/lib/python/site-packages/starlette/routing.py", line 78, in app
    await wrap_app_handling_exceptions(app, request)(scope, receive, send)
  File "/Users/amrehassan/Library/Python/3.9/lib/python/site-packages/starlette/_exception_handler.py", line 53, in wrapped_app
    raise exc
  File "/Users/amrehassan/Library/Python/3.9/lib/python/site-packages/starlette/_exception_handler.py", line 42, in wrapped_app
    await app(scope, receive, sender)
  File "/Users/amrehassan/Library/Python/3.9/lib/python/site-packages/starlette/routing.py", line 76, in app
    await response(scope, receive, send)
  File "/Users/amrehassan/Library/Python/3.9/lib/python/site-packages/starlette/responses.py", line 356, in __call__
    raise RuntimeError(f"File at path {self.path} does not exist.")
RuntimeError: File at path /var/folders/ld/jp4094td2sz94sf512yktxlw0000gn/T/docx_processor/8a7da7a8-eacb-4155-9a4f-3a0e217bc355/output_test_template.pdf does not exist.
